Workbook

Sheet MAX
A1: Station: Gantsi
A2: Mean Monthly Maximum temperatures
B3: Jul | C3: Aug | D3: Sep | E3: Oct | F3: Nov | G3: Dec | H3: Jan | I3: Feb | J3: Mar | K3: Apr | L3: May | M3: Jun | N3: Annual Av.
A4: 1993/94 | B4: 24.3 | C4: 26.6 | D4: 31.8 | E4: 33.2 | F4: 33.2 | G4: 34.7 | H4: 29.3 | I4: 30.8 | J4: 34.3 | K4: 30.6 | L4: 27.4 | M4: 22.4 | N4: =AVERAGE(B4:M4) -> 29.883333
A5: 1994/95 | B5: 21.9 | C5: 26.2 | D5: 32 | E5: 33.9 | F5: 33.9 | G5: 35.9 | H5: 36.4 | I5: 34.3 | J5: 32.7 | K5: 30.8 | L5: 25.4 | M5: 23.9 | N5: =AVERAGE(B5:M5) -> 30.608333
A6: 1995/96 | B6: 24.8 | C6: 27.4 | D6: 32.3 | E6: 33.8 | F6: 34.5 | G6: 32.5 | H6: 31.6 | I6: 30.8 | J6: 31.3 | K6: 29.6 | L6: 26.6 | M6: 24.8 | N6: =AVERAGE(B6:M6) -> 30
A7: 1996/97 | B7: 22.8 | C7: 27.6 | D7: 31.5 | E7: 36.2 | F7: 33.1 | G7: 34.3 | H7: 30.6 | I7: 32.2 | J7: 28.8 | K7: 28 | L7: 25.2 | M7: 24.8 | N7: =AVERAGE(B7:M7) -> 29.591667
A8: 1997/98 | B8: 24.2 | C8: 28.5 | D8: 30.4 | E8: 32.6 | F8: 34.9 | G8: 35.3 | H8: 32.8 | I8: 34.7 | J8: 34 | K8: 32.2 | L8: 28.1 | M8: 26.8 | N8: =AVERAGE(B8:M8) -> 31.208333
A9: 1998/99 | B9: 25.4 | C9: 26.3 | D9: 32.9 | E9: 33.9 | F9: 33.3 | G9: 31.5 | H9: 33.8 | I9: 34.6 | J9: 32.7 | K9: 31.5 | L9: 28.5 | M9: 25.5 | N9: =AVERAGE(B9:M9) -> 30.825
A10: 1999/00 | B10: 24 | C10: 26.9 | D10: 30.1 | E10: 32.1 | F10: 34.4 | G10: 30.7 | H10: 29.3 | I10: 28.9 | J10: 28.6 | K10: 27.7 | L10: 25.7 | M10: 23.7 | N10: =AVERAGE(B10:M10) -> 28.508333
A11: 2000/01 | B11: 23.1 | C11: 26.8 | D11: 31.3 | E11: 34.2 | F11: 33.7 | G11: 33.5 | H11: 35.6 | I11: 32.3 | J11: 30.7 | K11: 29.1 | L11: 25.9 | M11: 24.5 | N11: =AVERAGE(B11:M11) -> 30.058333
A12: 2001/02 | B12: 23.3 | C12: 27.9 | D12: 31.3 | E12: 34.7 | F12: 31.9 | G12: 34.3 | H12: 34.8 | I12: 32.9 | J12: 33 | K12: 31.6 | L12: 28.1 | M12: 23.2 | N12: =AVERAGE(B12:M12) -> 30.583333
A13: 2002/03 | B13: 25.9 | C13: 28.1 | D13: 30.8 | E13: 33.9 | F13: 32.8 | G13: 34 | H13: 35.8 | I13: 33.6 | J13: 33.6 | K13: 31.7 | L13: 27.6 | M13: 23.6 | N13: =AVERAGE(B13:M13) -> 30.95
A14: 2003/04 | B14: 23.8 | C14: 26.8 | D14: 32.5 | E14: 33.8 | F14: 33.9 | G14: 34.4 | H14: 32.8 | I14: 31.9 | J14: 28.8 | K14: 28.7 | L14: 26.8 | M14: 23.2 | N14: =AVERAGE(B14:M14) -> 29.783333
A15: 2004/05 | B15: 22.9 | C15: 28.7 | D15: 30.5 | E15: 33.3 | F15: 35.1 | G15: 34.3 | H15: 34.5 | I15: 33.4 | J15: 32 | K15: 28.8 | L15: 28.8 | M15: 27.1 | N15: =AVERAGE(B15:M15) -> 30.783333
... A34: 2023/24 | B34: 24.1 | C34: 28.3 | D34: 32.7 | E34: 36.8 | F34: 35.5 | G34: 34.7 | H34: 33.6 | I34: 36.8 | J34: 35.8 | K34: 32.6 | L34: 29.1 | M34: 24.6 | N34: =AVERAGE(B34:M34) -> 32.05
A35: MONTHLY AVE | B35: =AVERAGE(B4:B34) -> 24.064568 | C35: =AVERAGE(C4:C34) -> 27.716753 | D35: =AVERAGE(D4:D34) -> 31.860297 | E35: =AVERAGE(E4:E34) -> 34.108377 | F35: =AVERAGE(F4:F34) -> 33.50271 | G35: =AVERAGE(G4:G34) -> 33.312344 | H35: =AVERAGE(H4:H34) -> 32.501713 | I35: =AVERAGE(I4:I34) -> 31.970644 | ... M35: =AVERAGE(M4:M34) -> 24.631724
A39: Station: Shakawe
A40: Mean Monthly Maximum temperatures
B41: Jul | C41: Aug | D41: Sep | E41: Oct | F41: Nov | G41: Dec | H41: Jan | I41: Feb | J41: Mar | K41: Apr | L41: May | M41: Jun | N41: Annual Av.
A42: 1993/94 | B42: 26.1 | C42: 29.7 | D42: 32.8 | E42: 35.4 | F42: 33.7 | G42: 33.1 | H42: 29.1 | I42: 30.2 | J42: 33.9 | K42: 32.1 | L42: 28.9 | M42: 25.1 | N42: =AVERAGE(B42:M42) -> 30.841667
A43: 1994/95 | B43: 24.2 | C43: 29.1 | D43: 34 | E43: 35.3 | F43: 34.8 | G43: 35 | H43: 35.3 | I43: 30.7 | J43: 32.8 | K43: 31.6 | L43: 28.4 | M43: 25.7 | N43: =AVERAGE(B43:M43) -> 31.408333
A44: 1995/96 | B44: 27.3 | C44: 30.6 | D44: 34.2 | E44: 36.4 | F44: 36 | G44: 33.3 | H44: 30.9 | I44: 31.9 | J44: 32.2 | K44: 31.7 | L44: 29.3 | M44: 26.3 | N44: =AVERAGE(B44:M44) -> 31.675
A45: 1996/97 | B45: 25.4 | C45: 31.1 | D45: 33.8 | E45: 37.2 | F45: 33.9 | G45: 33.9 | H45: 30.1 | I45: 30.6 | J45: 30.5 | K45: 30.5 | L45: 27.4 | M45: 27.1 | N45: =AVERAGE(B45:M45) -> 30.958333
A46: 1997/98 | B46: 26.2 | C46: 30.6 | D46: 33 | E46: 33.7 | F46: 34.8 | G46: 34.8 | H46: 31.7 | I46: 33.4 | J46: 33.7 | K46: 32.5 | L46: 29.8 | M46: 27.4 | N46: =AVERAGE(B46:M46) -> 31.8
A47: 1998/99 | B47: 27 | C47: 28.6 | D47: 34.5 | E47: 35.8 | F47: 33.6 | G47: 30.8 | H47: 31.6 | I47: 32.4 | J47: 31.9 | K47: 31.6 | L47: 29.9 | M47: 27.2 | N47: =AVERAGE(B47:M47) -> 31.241667
A48: 1999/00 | B48: 26 | C48: 29.3 | D48: 32.2 | E48: 34.5 | F48: 34.5 | G48: 30.7 | H48: 28.5 | I48: 29.8 | J48: 30.3 | K48: 29.9 | L48: 27.8 | M48: 25.9 | N48: =AVERAGE(B48:M48) -> 29.95
A49: 2000/01 | B49: 25.3 | C49: 28 | D49: 33.2 | E49: 35.6 | F49: 35.7 | G49: 31.9 | H49: 33.1 | I49: 29.4 | J49: 29.7 | K49: 29.9 | L49: 27.8 | M49: 26.3 | N49: =AVERAGE(B49:M49) -> 30.491667
A50: 2001/02 | B50: 24.9 | C50: 30.4 | D50: 33.5 | E50: 35.2 | F50: 31.7 | G50: 33 | H50: 33.4 | I50: 33.3 | J50: 33.6 | K50: 31.4 | L50: 29.6 | M50: 25.4 | N50: =AVERAGE(B50:M50) -> 31.283333
A51: 2002/03 | B51: 28.3 | C51: 29.8 | D51: 32.5 | E51: 34.7 | F51: 33.7 | G51: 33.8 | H51: 33.7 | I51: 31.9 | J51: 33.4 | K51: 31.5 | L51: 28.8 | M51: 25.9 | N51: =AVERAGE(B51:M51) -> 31.5
A52: 2003/04 | B52: 25.6 | C52: 28.9 | D52: 34.1 | E52: 35.6 | F52: 34.4 | G52: 32.1 | H52: 30.6 | I52: 31.1 | J52: 29 | K52: 29.2 | L52: 26.9 | M52: 24.8 | N52: =AVERAGE(B52:M52) -> 30.191667
A53: 2004/05 | B53: 24.8 | C53: 30.5 | D53: 32.3 | E53: 35.3 | F53: 35.2 | G53: 32.8 | H53: 34 | I53: 33.5 | J53: 31.4 | K53: 32 | L53: 30.4 | M53: 28.7 | N53: =AVERAGE(B53:M53) -> 31.741667
... A68: 2019/20 | B68: 27.9 | C68: 30.9 | D68: 32.9 | E68: 36.6 | F68: 36 | G68: 34.7 | H68: 35 | I68: 35.1 | J68: 31.8 | K68: 31.3 | L68: 29.2 | M68: 27.1 | N68: =AVERAGE(B68:M68) -> 32.375
A69: 2020/21 | B69: =AVERAGE(B39:B65) -> 26.054203 | C69: =AVERAGE(C39:C65) -> 29.787132 | D69: =AVERAGE(D39:D65) -> 33.447904 | E69: =AVERAGE(E39:E65) -> 35.593936 | F69: =AVERAGE(F39:F65) -> 33.990158 | G69: =AVERAGE(G39:G65) -> 32.249872 | H69: =AVERAGE(H39:H64) -> 32.004348 | I69: =AVERAGE(I39:I64) -> 31.408696 | J69: =AVERAGE(J39:J64) -> 31.382609 | K69: =AVERAGE(B39:J63) -> 31.665152 | L69: =AVERAGE(C39:K63) -> 32.181313 | M69: =AVERAGE(D39:L63) -> 32.093434 | N69: =AVERAGE(B69:M69) -> 31.821563
A70: 2021/22 | B70: =AVERAGE(B40:B66) -> 26.084034 | C70: =AVERAGE(C40:C66) -> 29.783646 | D70: =AVERAGE(D40:D66) -> 33.419976 | E70: =AVERAGE(E40:E66) -> 35.602179 | F70: 36.1 | G70: 32.3 | H70: 29.5 | I70: 31.8 | J70: 29.4 | K70: 30.1 | L70: 27.8 | M70: 25.6 | N70: =AVERAGE(B70:M70) -> 30.624153
A71: 2022/23 | B71: 27 | C71: 31 | D71: 34.2 | E71: 35.6 | F71: 34.1 | G71: 32.3 | H71: 31.8 | I71: 33.1 | J71: 33.6 | K71: 34 | L71: 32.2 | M71: 29.1 | N71: =AVERAGE(B71:M71) -> 32.333333
A72: 2023/24 | B72: 26.6 | C72: 30.6 | D72: 35.6 | E72: 38.2 | F72: 36.1 | G72: 33.1 | H72: 31.8 | I72: 36 | J72: 31.4 | K72: 30.8 | L72: 30.5 | M72: 26.9 | N72: =AVERAGE(B72:M72) -> 32.3
A73: MONTHLY AVE | B73: =AVERAGE(B42:B72) -> 26.172229 | C73: =AVERAGE(C42:C72) -> 29.956837 | D73: =AVERAGE(D42:D72) -> 33.537654 | E73: =AVERAGE(E42:E72) -> 35.701632 | F73: =AVERAGE(F42:F72) -> 34.301741 | G73: =AVERAGE(G42:G72) -> 32.466026 | H73: =AVERAGE(H42:H72) -> 31.955996 | I73: =AVERAGE(I42:I72) -> 31.6777 | ... M73: =AVERAGE(M42:M72) -> 26.761079
A76: Station: Maun
A77: Mean Monthly Maximum temperatures
...

Sheet HAZARD INPUT TEMP
A1: Station | B1: Year | C1: Annual_mean_max_C | D1: Months_present | E1: Scenario
A2: Sir Seretse Khama Airport | B2: 1993/94 | C2: =MAX!N153 -> 28.335115 | D2: 12 | E2: Historical
A3: Sir Seretse Khama Airport | B3: 1994/95 | C3: =MAX!N154 -> 28.637822 | D3: 12 | E3: Historical
A4: Sir Seretse Khama Airport | B4: 1995/96 | C4: =MAX!N155 -> 27.917299 | D4: 12 | E4: Historical
A5: Sir Seretse Khama Airport | B5: 1996/97 | C5: =MAX!N156 -> 27.55662 | D5: 12 | E5: Historical
A6: Sir Seretse Khama Airport | B6: 1997/98 | C6: =MAX!N157 -> 29.229489 | D6: 12 | E6: Historical
A7: Sir Seretse Khama Airport | B7: 1998/99 | C7: =MAX!N158 -> 28.78738 | D7: 12 | E7: Historical
A8: Sir Seretse Khama Airport | B8: 1999/00 | C8: =MAX!N159 -> 26.836816 | D8: 12 | E8: Historical
A9: Sir Seretse Khama Airport | B9: 2000/01 | C9: =MAX!N160 -> 27.787011 | D9: 12 | E9: Historical
A10: Sir Seretse Khama Airport | B10: 2001/02 | C10: =MAX!N161 -> 27.801559 | D10: 12 | E10: Historical
A11: Sir Seretse Khama Airport | B11: 2002/03 | C11: =MAX!N162 -> 29.273059 | D11: 12 | E11: Historical
A12: Sir Seretse Khama Airport | B12: 2003/04 | C12: =MAX!N163 -> 28.133057 | D12: 12 | E12: Historical
A13: Sir Seretse Khama Airport | B13: 2004/05 | C13: =MAX!N164 -> 29.102196 | D13: 12 | E13: Historical
... A32: Sir Seretse Khama Airport | B32: 2023/24 | C32: =MAX!N183 -> 29.75 | D32: 12 | E32: Historical

Sheet HAZARD INPUT RAINFALL
A1: Station | B1: Year | C1: Annual_total_mm | D1: Months_present | E1: Scenario
A2: Sir Seretse Khama Airport | B2: 1993/94 | C2: 488.7 | D2: 12 | E2: Historical
A3: Sir Seretse Khama Airport | B3: 1994/95 | C3: 366.7 | D3: 12 | E3: Historical
A4: Sir Seretse Khama Airport | B4: 1995/96 | C4: 636.8 | D4: 12 | E4: Historical
A5: Sir Seretse Khama Airport | B5: 1996/97 | C5: 731.1 | D5: 12 | E5: Historical
A6: Sir Seretse Khama Airport | B6: 1997/98 | C6: 454.7 | D6: 12 | E6: Historical
A7: Sir Seretse Khama Airport | B7: 1998/99 | C7: 303.9 | D7: 12 | E7: Historical
A8: Sir Seretse Khama Airport | B8: 1999/00 | C8: 853.1 | D8: 12 | E8: Historical
A9: Sir Seretse Khama Airport | B9: 2000/01 | C9: 567 | D9: 12 | E9: Historical
A10: Sir Seretse Khama Airport | B10: 2001/02 | C10: 639.6 | D10: 12 | E10: Historical
A11: Sir Seretse Khama Airport | B11: 2002/03 | C11: 361.4 | D11: 12 | E11: Historical
A12: Sir Seretse Khama Airport | B12: 2003/04 | C12: 475.6 | D12: 12 | E12: Historical
A13: Sir Seretse Khama Airport | B13: 2004/05 | C13: 357.3 | D13: 12 | E13: Historical
... A33: Sir Seretse Khama Airport | B33: 2024/25 | C33: 462.8 | D33: 12 | E33: Historical

Sheet MIN
A1: Station: Gantsi
A2: Mean Monthly Minimum temperatures
B3: Jul | C3: Aug | D3: Sep | E3: Oct | F3: Nov | G3: Dec | H3: Jan | I3: Feb | J3: Mar | K3: Apr | L3: May | M3: Jun | N3: Annual Av.
A4: 1993/94 | B4: 6.4 | C4: 7.8 | D4: 11.2 | E4: 18.6 | F4: 18.1 | G4: 20 | H4: 19 | I4: 17.5 | J4: 17 | K4: 12.9 | L4: 6.9 | M4: 3.4 | N4: =AVERAGE(B4:M4) -> 13.233333
A5: 1994/95 | B5: 1.2 | C5: 5.6 | D5: 11.7 | E5: 14.5 | F5: 19.8 | G5: 20.6 | H5: 21.1 | I5: 19 | J5: 18.3 | K5: 14.4 | L5: 11.3 | M5: 5 | N5: =AVERAGE(B5:M5) -> 13.541667
A6: 1995/96 | B6: 5.4 | C6: 7.7 | D6: 13.7 | E6: 15.8 | F6: 18.5 | G6: 17.7 | H6: 19.3 | I6: 17.6 | J6: 15.4 | K6: 12.9 | L6: 9.7 | M6: 6.3 | N6: =AVERAGE(B6:M6) -> 13.333333
A7: 1996/97 | B7: 3.4 | C7: 6.3 | D7: 12 | E7: 18 | F7: 17.9 | G7: 19.5 | H7: 19.5 | I7: 18.5 | J7: 17.7 | K7: 12.5 | L7: 8.4 | M7: 5 | N7: =AVERAGE(B7:M7) -> 13.225
A8: 1997/98 | B8: 5.8 | C8: 7.9 | D8: 13.1 | E8: 16.2 | F8: 17.3 | G8: 20.6 | H8: 19.4 | I8: 19.5 | J8: 18.9 | K8: 15.4 | L8: 7.2 | M8: 5.1 | N8: =AVERAGE(B8:M8) -> 13.866667
A9: 1998/99 | B9: 5.9 | C9: 7.4 | D9: 13.5 | E9: 17.6 | F9: 19 | G9: 18.8 | H9: 18.6 | I9: 19.1 | J9: 17.9 | K9: 14.2 | L9: 11.4 | M9: 6.2 | N9: =AVERAGE(B9:M9) -> 14.133333
A10: 1999/00 | B10: 7 | C10: 7.7 | D10: 11 | E10: 15.1 | F10: 19.5 | G10: 19.1 | H10: 17.7 | I10: 18.5 | J10: 17.8 | K10: 13.2 | L10: 8 | M10: 6.4 | N10: =AVERAGE(B10:M10) -> 13.416667
A11: 2000/01 | B11: 4.7 | C11: 7.5 | D11: 11.8 | E11: 16.6 | F11: 15.8 | G11: 18.2 | H11: 18.8 | I11: 19 | J11: 17.3 | K11: 15.6 | L11: 8.4 | M11: 5.2 | N11: =AVERAGE(B11:M11) -> 13.241667
A12: 2001/02 | B12: 4 | C12: 8.1 | D12: 10.2 | E12: 16.6 | F12: 17.9 | G12: 18.4 | H12: 19.3 | I12: 18.4 | J12: 16.5 | K12: 13.8 | L12: 8.3 | M12: 3.5 | N12: =AVERAGE(B12:M12) -> 12.916667
A13: 2002/03 | B13: 4.1 | C13: 9.2 | D13: 10.7 | E13: 15.5 | F13: 16.9 | G13: 18.9 | H13: 19.2 | I13: 18.4 | J13: 16.3 | K13: 14.1 | L13: 8.2 | M13: 5.1 | N13: =AVERAGE(B13:M13) -> 13.05
A14: 2003/04 | B14: 3.8 | C14: 6.7 | D14: 13.3 | E14: 17.1 | F14: 19.5 | G14: 19.6 | H14: 19.5 | I14: 18.4 | J14: 17.8 | K14: 13.2 | L14: 7.8 | M14: 4 | N14: =AVERAGE(B14:M14) -> 13.391667
A15: 2004/05 | B15: 3.8 | C15: 9 | D15: 10.9 | E15: 15.4 | F15: 19.1 | G15: 20.1 | H15: 20.7 | I15: 19.6 | J15: 17.9 | K15: 15.6 | L15: 10.2 | M15: 8.2 | N15: =AVERAGE(B15:M15) -> 14.208333
... A34: 2023/24 | B34: 5.4 | C34: 9.1 | D34: 12.7 | E34: 17.7 | F34: 20.2 | G34: 20.3 | H34: 19.8 | I34: 21.7 | J34: 20.3 | K34: 13.9 | L34: 9.4 | M34: 5.6 | N34: =AVERAGE(B34:M34) -> 14.675
A35: Mnthly Av. | B35: =AVERAGE(B4:B34) -> 5.0282057 | C35: =AVERAGE(C4:C34) -> 8.1067939 | D35: =AVERAGE(D4:D34) -> 12.230164 | E35: =AVERAGE(E4:E34) -> 16.562521 | F35: =AVERAGE(F4:F34) -> 18.388419 | G35: =AVERAGE(G4:G34) -> 18.997493 | H35: =AVERAGE(H4:H34) -> 19.349343 | I35: =AVERAGE(I4:I34) -> 18.929823 | ... M35: =AVERAGE(M4:M34) -> 5.5734595
A37: Station: Shakawe
A38: Mean Monthly Minimum temperatures
B39: Jul | C39: Aug | D39: Sep | E39: Oct | F39: Nov | G39: Dec | H39: Jan | I39: Feb | J39: Mar | K39: Apr | L39: May | M39: Jun | N39: Annual Av.
A40: 1993/94 | B40: 7.3 | C40: 8.4 | D40: 10.5 | E40: 13.4 | F40: 18.7 | G40: 19.5 | H40: 20.3 | I40: 18.9 | J40: 16.5 | K40: 14.4 | L40: 8.1 | M40: 4.5 | N40: =AVERAGE(B40:M40) -> 13.375
A41: 1994/95 | B41: 3.1 | C41: 7.2 | D41: 11.7 | E41: 16.8 | F41: 20.4 | G41: 19.9 | H41: 20.4 | I41: 18.8 | J41: 18.2 | K41: 14.6 | L41: 13.3 | M41: 5.4 | N41: =AVERAGE(B41:M41) -> 14.15
A42: 1995/96 | B42: 5.7 | C42: 9.9 | D42: 14.3 | E42: 18.7 | F42: 19.8 | G42: 19.4 | H42: 20 | I42: 19.4 | J42: 17.5 | K42: 15.2 | L42: 11.3 | M42: 5.9 | N42: =AVERAGE(B42:M42) -> 14.758333
A43: 1996/97 | B43: 4.1 | C43: 8.7 | D43: 14 | E43: 19.6 | F43: 19.6 | G43: 20.1 | H43: 19.8 | I43: 19.1 | J43: 19.3 | K43: 13.1 | L43: 8.6 | M43: 5.8 | N43: =AVERAGE(B43:M43) -> 14.316667
A44: 1997/98 | B44: 7.3 | C44: 8.3 | D44: 15.1 | E44: 17.3 | F44: 19.5 | G44: 21 | H44: 20.6 | I44: 21.1 | J44: 20.4 | K44: 16.7 | L44: 8.6 | M44: 5 | N44: =AVERAGE(B44:M44) -> 15.075
A45: 1998/99 | B45: 7.4 | C45: 9.3 | D45: 14.4 | E45: 19.2 | F45: 19.6 | G45: 19.3 | H45: 19.2 | I45: 18.6 | J45: 18.4 | K45: 15.1 | L45: 11.5 | M45: 7.2 | N45: =AVERAGE(B45:M45) -> 14.933333
A46: 1999/00 | B46: 7.2 | C46: 8.4 | D46: 12 | E46: 17 | F46: 19 | G46: 19.5 | H46: 18.9 | I46: 19.5 | J46: 27.6 | K46: 14.2 | L46: 9.7 | M46: 7.7 | N46: =AVERAGE(B46:M46) -> 15.058333
A47: 2000/01 | B47: 5.8 | C47: 7.3 | D47: 13.6 | E47: 15.9 | F47: 17.3 | G47: 19.5 | H47: 18.8 | I47: 19.9 | J47: 18.3 | K47: 17.2 | L47: 11.2 | M47: 6.9 | N47: =AVERAGE(B47:M47) -> 14.308333
A48: 2001/02 | B48: 5.4 | C48: 10.1 | D48: 14.3 | E48: 16.5 | F48: 19.7 | G48: 19.4 | H48: 19.9 | I48: 19.4 | J48: 19.4 | K48: 15.5 | L48: 9.5 | M48: 6.8 | N48: =AVERAGE(B48:M48) -> 14.658333
A49: 2002/03 | B49: 6 | C49: 10.9 | D49: 13.1 | E49: 17.6 | F49: 19.2 | G49: 20.4 | H49: 20.5 | I49: 20.4 | J49: 19.4 | K49: 16.4 | L49: 10.5 | M49: 9.6 | N49: =AVERAGE(B49:M49) -> 15.333333
A50: 2003/04 | B50: 5.3 | C50: 7 | D50: 13.5 | E50: 17.1 | F50: 20 | G50: 20.3 | H50: 20.1 | I50: 20 | J50: 19.8 | K50: 15.8 | L50: 7.6 | M50: 5.7 | N50: =AVERAGE(B50:M50) -> 14.35
A51: 2004/05 | B51: 4.6 | C51: 9.6 | D51: 11.5 | E51: 15.9 | F51: 19.3 | G51: 19.6 | H51: 20.6 | I51: 20.2 | J51: 19.9 | K51: 16.8 | L51: 11.7 | M51: 7.4 | N51: =AVERAGE(B51:M51) -> 14.758333
... A70: 2023/24 | B70: 5.8 | C70: 9 | D70: 13.4 | E70: 19.4 | F70: 20.9 | G70: 20.9 | H70: 19.2 | I70: 19.8 | J70: 18.9 | K70: 13.9 | L70: 9.4 | M70: 6.2 | N70: =AVERAGE(B70:M70) -> 14.733333
A71: Mnthly Av. | B71: =AVERAGE(B40:B70) -> 5.6 | C71: =AVERAGE(C40:C70) -> 8.2677419 | D71: =AVERAGE(D40:D70) -> 12.575118 | E71: =AVERAGE(E40:E70) -> 17.390323 | F71: =AVERAGE(F40:F70) -> 19.264516 | G71: =AVERAGE(G40:G70) -> 19.496762 | H71: =AVERAGE(H40:H70) -> 19.866519 | I71: =AVERAGE(I40:I70) -> 19.548387 | ... M71: =AVERAGE(M40:M70) -> 6.1322581
A73: Station: Maun
A74: Mean Monthly Minimum temperatures
B75: Jul | C75: Aug | D75: Sep | E75: Oct | F75: Nov | G75: Dec | H75: Jan | I75: Feb | J75: Mar | K75: Apr | L75: May | M75: Jun | N75: Annual Av.
A76: 1993/94 | B76: 10.2 | C76: 10.9 | D76: 14.8 | E76: 21.3 | F76: 20.8 | G76: 20.8 | H76: 20 | I76: 18.9 | J76: 18.3 | K76: 15.5 | L76: 10.4 | M76: 6.9 | N76: =AVERAGE(B76:M76) -> 15.733333
A77: 1994/95 | B77: 5.1 | C77: 9.8 | D77: 15.3 | E77: 18 | F77: 21.7 | G77: 21.4 | H77: 22.2 | I77: 21 | J77: 21 | K77: 16.7 | L77: 14.5 | M77: 8.7 | N77: =AVERAGE(B77:M77) -> 16.283333
A78: 1995/96 | B78: 9.3 | C78: 13.1 | D78: 17.2 | E78: 20.6 | F78: 22.2 | G78: 19.9 | H78: 20.6 | I78: 19.4 | J78: 17 | K78: 14.5 | L78: 11.3 | M78: 8.1 | N78: =AVERAGE(B78:M78) -> 16.1
...

Sheet Hazard_Input_Temp.
B5: Station | C5: Year | D5: Month | E5: Max_temp_C | F5: Scenario
B6: Sir Seretse Khama Airport | C6: 1993/94 | D6: July | E6: 24.3 | F6: Historical
B7: Sir Seretse Khama Airport | C7: 1993/94 | D7: august | E7: 26.6 | F7: Historical
B8: Sir Seretse Khama Airport | C8: 1993/94 | D8: september | E8: 31.8 | F8: Historical
B9: Sir Seretse Khama Airport | C9: 1993/94 | D9: October | E9: 33.2 | F9: Historical
B10: Sir Seretse Khama Airport | C10: 1993/94 | D10: November | E10: 33.2 | F10: Historical
B11: Sir Seretse Khama Airport | C11: 1993/94 | D11: December | E11: 34.7 | F11: Historical
B12: Sir Seretse Khama Airport | C12: 1993/94 | D12: January | E12: 29.3 | F12: Historical
B13: Sir Seretse Khama Airport | C13: 1993/94 | D13: February | E13: 30.8 | F13: Historical
B14: Sir Seretse Khama Airport | C14: 1993/94 | D14: March | E14: 34.3 | F14: Historical
B15: Sir Seretse Khama Airport | C15: 1993/94 | D15: April | E15: 30.6 | F15: Historical
B16: Sir Seretse Khama Airport | C16: 1993/94 | D16: May | E16: 27.4 | F16: Historical
B17: Sir Seretse Khama Airport | C17: 1993/94 | D17: June | E17: 22.4 | F17: Historical
B18: Sir Seretse Khama Airport
B19: Sir Seretse Khama Airport | C19: 1994/95 | D19: July | F19: Historical
B20: Sir Seretse Khama Airport | C20: 1994/95 | D20: August | F20: Historical
B21: Sir Seretse Khama Airport | C21: 1994/95 | D21: September | F21: Historical
B22: Sir Seretse Khama Airport | C22: 1994/95 | D22: October | F22: Historical
B23: Sir Seretse Khama Airport | C23: 1994/95 | D23: November | F23: Historical
B24: Sir Seretse Khama Airport | C24: 1994/95 | D24: December | F24: Historical
B25: Sir Seretse Khama Airport | C25: 1994/95 | D25: January | F25: Historical
B26: Sir Seretse Khama Airport | C26: 1994/95 | D26: February | F26: Historical
B27: Sir Seretse Khama Airport | C27: 1994/95 | D27: March | F27: Historical
B28: Sir Seretse Khama Airport | C28: 1994/95 | D28: April | F28: Historical
B29: Sir Seretse Khama Airport | C29: 1994/95 | D29: May | F29: Historical
B30: Sir Seretse Khama Airport | C30: 1994/95 | D30: June | F30: Historical
B31: Sir Seretse Khama Airport
B32: Sir Seretse Khama Airport | C32: 1995/96 | D32: July | F32: Historical
B33: Sir Seretse Khama Airport | C33: 1995/96 | D33: August | F33: Historical
B34: Sir Seretse Khama Airport | C34: 1995/96 | D34: September | F34: Historical
B35: Sir Seretse Khama Airport | C35: 1995/96 | D35: October | F35: Historical
B36: Sir Seretse Khama Airport | C36: 1995/96 | D36: November | F36: Historical
B37: Sir Seretse Khama Airport | C37: 1995/96 | D37: December | F37: Historical
B38: Sir Seretse Khama Airport | C38: 1995/96 | D38: January | F38: Historical
B39: Sir Seretse Khama Airport | C39: 1995/96 | D39: February | F39: Historical
B40: Sir Seretse Khama Airport | C40: 1995/96 | D40: March | F40: Historical
B41: Sir Seretse Khama Airport | C41: 1995/96 | D41: April | F41: Historical
B42: Sir Seretse Khama Airport | C42: 1995/96 | D42: May | F42: Historical
B43: Sir Seretse Khama Airport | C43: 1995/96 | D43: June | F43: Historical
B44: Sir Seretse Khama Airport
...

Sheet HAZARD DATA
A1: Station | B1: Year | C1: Annual_mean_max_C | D1: Annual_total_mm | E1: Months_present | F1: Scenario
A2: Sir Seretse Khama Airport | B2: 1993/94 | C2: =MAX!N153 -> 28.335115 | D2: 488.7 | E2: 12 | F2: Historical
A3: Sir Seretse Khama Airport | B3: 1994/95 | C3: =MAX!N154 -> 28.637822 | D3: 366.7 | E3: 12 | F3: Historical
A4: Sir Seretse Khama Airport | B4: 1995/96 | C4: =MAX!N155 -> 27.917299 | D4: 636.8 | E4: 12 | F4: Historical
A5: Sir Seretse Khama Airport | B5: 1996/97 | C5: =MAX!N156 -> 27.55662 | D5: 731.1 | E5: 12 | F5: Historical
A6: Sir Seretse Khama Airport | B6: 1997/98 | C6: =MAX!N157 -> 29.229489 | D6: 454.7 | E6: 12 | F6: Historical
A7: Sir Seretse Khama Airport | B7: 1998/99 | C7: =MAX!N158 -> 28.78738 | D7: 303.9 | E7: 12 | F7: Historical
A8: Sir Seretse Khama Airport | B8: 1999/00 | C8: =MAX!N159 -> 26.836816 | D8: 853.1 | E8: 12 | F8: Historical
A9: Sir Seretse Khama Airport | B9: 2000/01 | C9: =MAX!N160 -> 27.787011 | D9: 567 | E9: 12 | F9: Historical
A10: Sir Seretse Khama Airport | B10: 2001/02 | C10: =MAX!N161 -> 27.801559 | D10: 639.6 | E10: 12 | F10: Historical
A11: Sir Seretse Khama Airport | B11: 2002/03 | C11: =MAX!N162 -> 29.273059 | D11: 361.4 | E11: 12 | F11: Historical
A12: Sir Seretse Khama Airport | B12: 2003/04 | C12: =MAX!N163 -> 28.133057 | D12: 475.6 | E12: 12 | F12: Historical
A13: Sir Seretse Khama Airport | B13: 2004/05 | C13: =MAX!N164 -> 29.102196 | D13: 357.3 | E13: 12 | F13: Historical
... A32: Sir Seretse Khama Airport | B32: 2023/24 | C32: =MAX!N183 -> 29.75 | D32: 267.9 | E32: 12 | F32: Historical

Sheet CAT Claims Data
A1: ClaimNum | B1: CatastropheCode | C1: RiskDescription | D1: Claim Cost | E1: CurrencyDesc | F1: LossDate
A2: 1234 | B2: 2025 Feb flooding | C2: Houseowners Combined | D2: 22549.66 | E2: PULA | F2: 2/19/2025
A3: 1235 | B3: 2025 Feb flooding | C3: Houseowners Combined | D3: 300000 | E3: PULA | F3: 2/19/2025
A4: 1236 | B4: 2025 Feb flooding | C4: Houseowners Combined | D4: 86243.5 | E4: PULA | F4: 2/19/2025
A5: 1237 | B5: 2025 Feb flooding | C5: Houseowners Combined | D5: 8901.06 | E5: PULA | F5: 2/21/2025
A6: 1238 | B6: 2025 Feb flooding | C6: Houseowners Combined | D6: 18055.13 | E6: PULA | F6: 2/19/2025
A7: 1239 | B7: 2025 Feb flooding | C7: Houseowners Combined | D7: 23770 | E7: PULA | F7: 2/19/2025
A8: 1240 | B8: 2025 Feb flooding | C8: Houseowners Combined | D8: 488260.34 | E8: PULA | F8: 2/20/2025
A9: 1241 | B9: 2025 Feb flooding | C9: Houseowners Combined | D9: 45725.58 | E9: PULA | F9: 2/19/2025
A10: 1242 | B10: 2025 Feb flooding | C10: Houseowners Combined | D10: 49468.4 | E10: PULA | F10: 2/19/2025
A11: 1243 | B11: 2025 Feb flooding | C11: Houseowners Combined | D11: 38208.93 | E11: PULA | F11: 2/19/2025
A12: 1244 | B12: 2025 Feb flooding | C12: Houseowners Combined | D12: 23834.8 | E12: PULA | F12: 2/20/2025
A13: 1245 | B13: 2025 Feb flooding | C13: Houseowners Combined | D13: 66231 | E13: PULA | F13: 2/19/2025
... A546: 1588 | B546: 2025 Feb flooding | C546: Assets All Risks | D546: 450000 | E546: PULA | F546: 2/20/2025
